<?xml version="1.0"?>
<robot name="mytwo">

  <!-- Base link -->
  <link name="base_link">
    <visual>
      <geometry>
        <cylinder length="0.6" radius="0.25"/>
      </geometry>
    </visual>
    <collision>
      <geometry>
        <cylinder length="0.6" radius="0.25"/>
      </geometry>
    </collision>
    <inertial>
      <mass value="0.25"/>
      <inertia ixx="0.0003" iyy="0.0003" izz="0.0003"
               ixy="0" ixz="0" iyz="0"/>
    </inertial>
  </link>

  <!-- Sub link -->
  <link name="sub_link">
    <visual>
      <geometry>
        <cylinder length="0.4" radius="0.15"/>
      </geometry>
    </visual>
    <collision>
      <geometry>
        <cylinder length="0.4" radius="0.15"/>
      </geometry>
    </collision>
    <inertial>
      <mass value="0.15"/>
      <inertia ixx="0.0001" iyy="0.0001" izz="0.0001"
               ixy="0" ixz="0" iyz="0"/>
    </inertial>
  </link>

  <!-- Joint connecting base_link to sub_link -->
  <joint name="base_to_sub" type="revolute">
    <parent link="base_link"/>
    <child link="sub_link"/>
    <axis xyz="1 0 0"/>
    <limit effort="10" upper="0" lower="-1.57" velocity="1"/>
    <origin rpy="0 0 0" xyz="0 0.5 0"/>
  </joint>

</robot>
